Workbook

Sheet INSTRUCCIONES
A6: Matriz estandarizada de atenciones · Dupla Violeta
A7: Gobernación de Nariño · Secretaría de Equidad de Género e Inclusión Social · Geovisor SEGIS
A9: Un archivo por año | B9: Use un solo archivo por año (MATRIZ_DUPLA_2026.xlsx) y agregue cada mes las atenciones nuevas al final. Así el código de caso sigue la numeración del año. Cada mes cargue el archivo completo al geovisor (pestaña Dupla Violeta → «Cargar matriz del mes»): los meses que ya existían se actualizan.
A10: Código de caso | B10: Se genera solo: CÓDIGO DANE - AÑO - CONSECUTIVO del municipio en el año. Ejemplo: 52001-2026-0001 es el primer caso de Pasto en 2026; 52001-2026-0002 el segundo; 52356-2026-0001 el primero de Ipiales. Con 4 cifras alcanza para 9.999 casos por municipio al año.
A11: No reordene las filas | B11: El consecutivo depende del orden de las filas. Agregue siempre al final. Si necesita ordenar o filtrar para revisar, use el filtro sin mover filas; si va a mover filas, primero copie la columna CODIGO_CASO y péguela como valores.
A12: Ubicación | B12: Elija SUBREGION, MUNICIPIO y ZONA. Si es urbana, diligencie COMUNA (Pasto y Tumaco) y BARRIO; si es rural, CORREGIMIENTO y VEREDA. Las listas de comuna, barrio, corregimiento y vereda muestran solo las del municipio elegido. Si el nombre no está en la lista, escríbalo (el archivo lo acepta).
A13: Listas desplegables | B13: En las demás columnas elija siempre de la lista. En Excel puede escribir las primeras letras para encontrar la opción.
A14: Validación | B14: La columna VALIDACION debe decir «OK». Si dice otra cosa, indica qué corregir (fecha, dato obligatorio, subregión que no corresponde al municipio, ningún tipo de violencia, edad fuera de rango).
A15: Privacidad | B15: NO incluya nombres, documentos, teléfonos, direcciones ni relatos. El seguimiento con datos personales se lleva en el registro interno de la Dupla, que no se carga al geovisor.
A16: Columnas grises | B16: CODIGO_CASO, ANIO, CODIGO_DANE y VALIDACION se calculan solas; no las borre ni escriba encima.
A18: Diccionario de columnas
A19: Columna | B19: Obligatoria | C19: Opciones o formato | D19: Ayuda
A20: CODIGO_CASO | B20: No | C20: Automática | D20: Se genera solo: código DANE del municipio - año - consecutivo
A21: FECHA_ATENCION | B21: Sí | C21: Fecha dd/mm/aaaa | D21: dd/mm/aaaa
A22: ANIO | B22: No | C22: Automática | D22: Se llena solo
A23: SUBREGION | B23: Sí | C23: Centro, Guambuyaco, Juanambú, La Cordillera, La Sabana, Los Abades, Obando, Occidente, Pacífico Sur, Piedemonte Costero, Río Mayo, Sanquianga, Telembí | D23: Subregión del municipio
A24: MUNICIPIO | B24: Sí | C24: Lista de los 64 municipios | D24: Municipio donde ocurrieron los hechos. Escriba la letra inicial para ubicarlo
A25: CODIGO_DANE | B25: No | C25: Automática | D25: Se llena solo
A26: ZONA | B26: Sí | C26: Urbana, Rural | D26: Urbana: cabecera, comuna o barrio. Rural: corregimiento o vereda
A27: COMUNA | B27: No | C27: Lista según el municipio (o escriba el nombre) | D27: Solo zona urbana de Pasto o Tumaco
A28: BARRIO | B28: No | C28: Lista según el municipio (o escriba el nombre) | D28: Lista para Pasto; en otros municipios escriba el nombre
A29: CORREGIMIENTO | B29: No | C29: Lista según el municipio (o escriba el nombre) | D29: Lista de centros poblados del municipio
A30: VEREDA | B30: No | C30: Lista según el municipio (o escriba el nombre) | D30: Lista de veredas del municipio (DANE)
A31: EDAD | B31: No | C31: Número entero | D31: Vacío si no se conoce
A32: HIJOS_MENORES | B32: No | C32: Sí, No, No registra
A33: EPS | B33: No | C33: Texto libre corto
A34: ETNIA | B34: Sí | C34: Mestiza, Indígena, Afrodescendiente, Gitana (Rrom), No registra
A35: IDENTIDAD_GENERO | B35: Sí | C35: Mujer, Mujer trans, Hombre, Hombre trans, Persona no binaria, Otra, No registra
A36: ORIENTACION_SEXUAL | B36: Sí | C36: Heterosexual, Lesbiana, Gay, Bisexual, Otra, No registra
A37: VICTIMA_CONFLICTO | B37: Sí | C37: Sí, No
A38: LIDERESA | B38: Sí | C38: Sí, No
A39: MIGRANTE | B39: Sí | C39: Sí, No
A40: DISCAPACIDAD | B40: Sí | C40: Sí, No
A41: V_PSICOLOGICA | B41: Sí | C41: Sí, No
A42: V_FISICA | B42: Sí | C42: Sí, No
A43: V_SEXUAL | B43: Sí | C43: Sí, No
... A47: LUGAR_HECHOS | B47: Sí | C47: Vivienda, Vía o espacio público, Lugar de trabajo, Institución educativa, Establecimiento de salud, Transporte público, Bar, discoteca u hotel, Zona rural (finca o campo), Medios digitales o redes sociales, Otro lugar, No registra
A48: AGRESOR | B48: Sí | C48: Pareja, Expareja, Padre o padrastro, Madre o madrastra, Hijo o hija, Hermano o hermana, Otro familiar, Conocido o vecino, Jefe, docente, funcionario o autoridad, Actor armado, Desconocido, Otro, No registra | D48: Relación de la persona agresora con la víctima
A49: REM_COMISARIA | B49: Sí | C49: Sí, No | D49: Remisión a Comisaría de Familia
A50: REM_FISCALIA | B50: Sí | C50: Sí, No
...

Sheet MATRIZ
A1: CODIGO_CASO | B1: FECHA_ATENCION | C1: ANIO | D1: SUBREGION | E1: MUNICIPIO | F1: CODIGO_DANE | G1: ZONA | H1: COMUNA | I1: BARRIO | J1: CORREGIMIENTO | K1: VEREDA | L1: EDAD | M1: HIJOS_MENORES | N1: EPS | O1: ETNIA | P1: IDENTIDAD_GENERO | Q1: ORIENTACION_SEXUAL | R1: VICTIMA_CONFLICTO | S1: LIDERESA | T1: MIGRANTE | U1: DISCAPACIDAD | V1: V_PSICOLOGICA | W1: V_FISICA | X1: V_SEXUAL | Y1: V_ECONOMICA | Z1: INTENTO_FEMINICIDIO | AA1: FEMINICIDIO | AB1: LUGAR_HECHOS | AC1: AGRESOR | AD1: REM_COMISARIA | AE1: REM_FISCALIA | AF1: REM_SALUD | AG1: REM_POLICIA | AH1: REM_DEFENSORIA | AI1: REM_ICBF | AJ1: SEGUIMIENTO | AK1: VALIDACION
A2: =IF(OR(F2="",F2="Revisar",C2=""),"",F2&"-"&C2&"-"&TEXT(COUNTIFS($F$2:F2,F2,$C$2:C2,C2),"0000")) | C2: =IF(ISNUMBER(B2),YEAR(B2),"") | F2: =IF(E2="","",IFERROR(VLOOKUP(E2,LISTAS!$A$2:$C$65,2,FALSE),"Revisar")) | AK2: =IF(COUNTA(B2:B2)+COUNTA(D2:E2)+COUNTA(G2:AJ2)=0,"",IF(COUNTBLANK(B2:B2)+COUNTBLANK(D2:E2)+COUNTBLANK(G2:G2)+COUNTBLANK(O2:AJ2)>0,"Faltan "&(COUNTBLANK(B2:B2)+COUNTBLANK(D2:E2)+COUNTBLANK(G2:G2)+COUNTBLANK(O2:AJ2))&" datos obligatorios",IF(NOT(ISNUMBER(B2)),"Fecha no válida",IF(N(B2)>TODAY(),"Fecha futura",IF(IFERROR(VLOOKUP(E2,LISTAS!$A$2:$C$65,3,FALSE),"")<>D2,"La subregión no corresponde al municipio",IF(IF(L2="",FALSE,OR(L2<0,L2>110)),"Edad fuera de rango",IF((V2="Sí")+(W2="Sí")+(X2="Sí")+(Y2="Sí")=0,"Marque al menos un tipo de violencia","OK")))))))
A3: =IF(OR(F3="",F3="Revisar",C3=""),"",F3&"-"&C3&"-"&TEXT(COUNTIFS($F$2:F3,F3,$C$2:C3,C3),"0000")) | C3: =IF(ISNUMBER(B3),YEAR(B3),"") | F3: =IF(E3="","",IFERROR(VLOOKUP(E3,LISTAS!$A$2:$C$65,2,FALSE),"Revisar")) | AK3: =IF(COUNTA(B3:B3)+COUNTA(D3:E3)+COUNTA(G3:AJ3)=0,"",IF(COUNTBLANK(B3:B3)+COUNTBLANK(D3:E3)+COUNTBLANK(G3:G3)+COUNTBLANK(O3:AJ3)>0,"Faltan "&(COUNTBLANK(B3:B3)+COUNTBLANK(D3:E3)+COUNTBLANK(G3:G3)+COUNTBLANK(O3:AJ3))&" datos obligatorios",IF(NOT(ISNUMBER(B3)),"Fecha no válida",IF(N(B3)>TODAY(),"Fecha futura",IF(IFERROR(VLOOKUP(E3,LISTAS!$A$2:$C$65,3,FALSE),"")<>D3,"La subregión no corresponde al municipio",IF(IF(L3="",FALSE,OR(L3<0,L3>110)),"Edad fuera de rango",IF((V3="Sí")+(W3="Sí")+(X3="Sí")+(Y3="Sí")=0,"Marque al menos un tipo de violencia","OK")))))))
A4: =IF(OR(F4="",F4="Revisar",C4=""),"",F4&"-"&C4&"-"&TEXT(COUNTIFS($F$2:F4,F4,$C$2:C4,C4),"0000")) | C4: =IF(ISNUMBER(B4),YEAR(B4),"") | F4: =IF(E4="","",IFERROR(VLOOKUP(E4,LISTAS!$A$2:$C$65,2,FALSE),"Revisar")) | AK4: =IF(COUNTA(B4:B4)+COUNTA(D4:E4)+COUNTA(G4:AJ4)=0,"",IF(COUNTBLANK(B4:B4)+COUNTBLANK(D4:E4)+COUNTBLANK(G4:G4)+COUNTBLANK(O4:AJ4)>0,"Faltan "&(COUNTBLANK(B4:B4)+COUNTBLANK(D4:E4)+COUNTBLANK(G4:G4)+COUNTBLANK(O4:AJ4))&" datos obligatorios",IF(NOT(ISNUMBER(B4)),"Fecha no válida",IF(N(B4)>TODAY(),"Fecha futura",IF(IFERROR(VLOOKUP(E4,LISTAS!$A$2:$C$65,3,FALSE),"")<>D4,"La subregión no corresponde al municipio",IF(IF(L4="",FALSE,OR(L4<0,L4>110)),"Edad fuera de rango",IF((V4="Sí")+(W4="Sí")+(X4="Sí")+(Y4="Sí")=0,"Marque al menos un tipo de violencia","OK")))))))
A5: =IF(OR(F5="",F5="Revisar",C5=""),"",F5&"-"&C5&"-"&TEXT(COUNTIFS($F$2:F5,F5,$C$2:C5,C5),"0000")) | C5: =IF(ISNUMBER(B5),YEAR(B5),"") | F5: =IF(E5="","",IFERROR(VLOOKUP(E5,LISTAS!$A$2:$C$65,2,FALSE),"Revisar")) | AK5: =IF(COUNTA(B5:B5)+COUNTA(D5:E5)+COUNTA(G5:AJ5)=0,"",IF(COUNTBLANK(B5:B5)+COUNTBLANK(D5:E5)+COUNTBLANK(G5:G5)+COUNTBLANK(O5:AJ5)>0,"Faltan "&(COUNTBLANK(B5:B5)+COUNTBLANK(D5:E5)+COUNTBLANK(G5:G5)+COUNTBLANK(O5:AJ5))&" datos obligatorios",IF(NOT(ISNUMBER(B5)),"Fecha no válida",IF(N(B5)>TODAY(),"Fecha futura",IF(IFERROR(VLOOKUP(E5,LISTAS!$A$2:$C$65,3,FALSE),"")<>D5,"La subregión no corresponde al municipio",IF(IF(L5="",FALSE,OR(L5<0,L5>110)),"Edad fuera de rango",IF((V5="Sí")+(W5="Sí")+(X5="Sí")+(Y5="Sí")=0,"Marque al menos un tipo de violencia","OK")))))))
A6: =IF(OR(F6="",F6="Revisar",C6=""),"",F6&"-"&C6&"-"&TEXT(COUNTIFS($F$2:F6,F6,$C$2:C6,C6),"0000")) | C6: =IF(ISNUMBER(B6),YEAR(B6),"") | F6: =IF(E6="","",IFERROR(VLOOKUP(E6,LISTAS!$A$2:$C$65,2,FALSE),"Revisar")) | AK6: =IF(COUNTA(B6:B6)+COUNTA(D6:E6)+COUNTA(G6:AJ6)=0,"",IF(COUNTBLANK(B6:B6)+COUNTBLANK(D6:E6)+COUNTBLANK(G6:G6)+COUNTBLANK(O6:AJ6)>0,"Faltan "&(COUNTBLANK(B6:B6)+COUNTBLANK(D6:E6)+COUNTBLANK(G6:G6)+COUNTBLANK(O6:AJ6))&" datos obligatorios",IF(NOT(ISNUMBER(B6)),"Fecha no válida",IF(N(B6)>TODAY(),"Fecha futura",IF(IFERROR(VLOOKUP(E6,LISTAS!$A$2:$C$65,3,FALSE),"")<>D6,"La subregión no corresponde al municipio",IF(IF(L6="",FALSE,OR(L6<0,L6>110)),"Edad fuera de rango",IF((V6="Sí")+(W6="Sí")+(X6="Sí")+(Y6="Sí")=0,"Marque al menos un tipo de violencia","OK")))))))
A7: =IF(OR(F7="",F7="Revisar",C7=""),"",F7&"-"&C7&"-"&TEXT(COUNTIFS($F$2:F7,F7,$C$2:C7,C7),"0000")) | C7: =IF(ISNUMBER(B7),YEAR(B7),"") | F7: =IF(E7="","",IFERROR(VLOOKUP(E7,LISTAS!$A$2:$C$65,2,FALSE),"Revisar")) | AK7: =IF(COUNTA(B7:B7)+COUNTA(D7:E7)+COUNTA(G7:AJ7)=0,"",IF(COUNTBLANK(B7:B7)+COUNTBLANK(D7:E7)+COUNTBLANK(G7:G7)+COUNTBLANK(O7:AJ7)>0,"Faltan "&(COUNTBLANK(B7:B7)+COUNTBLANK(D7:E7)+COUNTBLANK(G7:G7)+COUNTBLANK(O7:AJ7))&" datos obligatorios",IF(NOT(ISNUMBER(B7)),"Fecha no válida",IF(N(B7)>TODAY(),"Fecha futura",IF(IFERROR(VLOOKUP(E7,LISTAS!$A$2:$C$65,3,FALSE),"")<>D7,"La subregión no corresponde al municipio",IF(IF(L7="",FALSE,OR(L7<0,L7>110)),"Edad fuera de rango",IF((V7="Sí")+(W7="Sí")+(X7="Sí")+(Y7="Sí")=0,"Marque al menos un tipo de violencia","OK")))))))
A8: =IF(OR(F8="",F8="Revisar",C8=""),"",F8&"-"&C8&"-"&TEXT(COUNTIFS($F$2:F8,F8,$C$2:C8,C8),"0000")) | C8: =IF(ISNUMBER(B8),YEAR(B8),"") | F8: =IF(E8="","",IFERROR(VLOOKUP(E8,LISTAS!$A$2:$C$65,2,FALSE),"Revisar")) | AK8: =IF(COUNTA(B8:B8)+COUNTA(D8:E8)+COUNTA(G8:AJ8)=0,"",IF(COUNTBLANK(B8:B8)+COUNTBLANK(D8:E8)+COUNTBLANK(G8:G8)+COUNTBLANK(O8:AJ8)>0,"Faltan "&(COUNTBLANK(B8:B8)+COUNTBLANK(D8:E8)+COUNTBLANK(G8:G8)+COUNTBLANK(O8:AJ8))&" datos obligatorios",IF(NOT(ISNUMBER(B8)),"Fecha no válida",IF(N(B8)>TODAY(),"Fecha futura",IF(IFERROR(VLOOKUP(E8,LISTAS!$A$2:$C$65,3,FALSE),"")<>D8,"La subregión no corresponde al municipio",IF(IF(L8="",FALSE,OR(L8<0,L8>110)),"Edad fuera de rango",IF((V8="Sí")+(W8="Sí")+(X8="Sí")+(Y8="Sí")=0,"Marque al menos un tipo de violencia","OK")))))))
A9: =IF(OR(F9="",F9="Revisar",C9=""),"",F9&"-"&C9&"-"&TEXT(COUNTIFS($F$2:F9,F9,$C$2:C9,C9),"0000")) | C9: =IF(ISNUMBER(B9),YEAR(B9),"") | F9: =IF(E9="","",IFERROR(VLOOKUP(E9,LISTAS!$A$2:$C$65,2,FALSE),"Revisar")) | AK9: =IF(COUNTA(B9:B9)+COUNTA(D9:E9)+COUNTA(G9:AJ9)=0,"",IF(COUNTBLANK(B9:B9)+COUNTBLANK(D9:E9)+COUNTBLANK(G9:G9)+COUNTBLANK(O9:AJ9)>0,"Faltan "&(COUNTBLANK(B9:B9)+COUNTBLANK(D9:E9)+COUNTBLANK(G9:G9)+COUNTBLANK(O9:AJ9))&" datos obligatorios",IF(NOT(ISNUMBER(B9)),"Fecha no válida",IF(N(B9)>TODAY(),"Fecha futura",IF(IFERROR(VLOOKUP(E9,LISTAS!$A$2:$C$65,3,FALSE),"")<>D9,"La subregión no corresponde al municipio",IF(IF(L9="",FALSE,OR(L9<0,L9>110)),"Edad fuera de rango",IF((V9="Sí")+(W9="Sí")+(X9="Sí")+(Y9="Sí")=0,"Marque al menos un tipo de violencia","OK")))))))
A10: =IF(OR(F10="",F10="Revisar",C10=""),"",F10&"-"&C10&"-"&TEXT(COUNTIFS($F$2:F10,F10,$C$2:C10,C10),"0000")) | C10: =IF(ISNUMBER(B10),YEAR(B10),"") | F10: =IF(E10="","",IFERROR(VLOOKUP(E10,LISTAS!$A$2:$C$65,2,FALSE),"Revisar")) | AK10: =IF(COUNTA(B10:B10)+COUNTA(D10:E10)+COUNTA(G10:AJ10)=0,"",IF(COUNTBLANK(B10:B10)+COUNTBLANK(D10:E10)+COUNTBLANK(G10:G10)+COUNTBLANK(O10:AJ10)>0,"Faltan "&(COUNTBLANK(B10:B10)+COUNTBLANK(D10:E10)+COUNTBLANK(G10:G10)+COUNTBLANK(O10:AJ10))&" datos obligatorios",IF(NOT(ISNUMBER(B10)),"Fecha no válida",IF(N(B10)>TODAY(),"Fecha futura",IF(IFERROR(VLOOKUP(E10,LISTAS!$A$2:$C$65,3,FALSE),"")<>D10,"La subregión no corresponde al municipio",IF(IF(L10="",FALSE,OR(L10<0,L10>110)),"Edad fuera de rango",IF((V10="Sí")+(W10="Sí")+(X10="Sí")+(Y10="Sí")=0,"Marque al menos un tipo de violencia","OK")))))))
A11: =IF(OR(F11="",F11="Revisar",C11=""),"",F11&"-"&C11&"-"&TEXT(COUNTIFS($F$2:F11,F11,$C$2:C11,C11),"0000")) | C11: =IF(ISNUMBER(B11),YEAR(B11),"") | F11: =IF(E11="","",IFERROR(VLOOKUP(E11,LISTAS!$A$2:$C$65,2,FALSE),"Revisar")) | AK11: =IF(COUNTA(B11:B11)+COUNTA(D11:E11)+COUNTA(G11:AJ11)=0,"",IF(COUNTBLANK(B11:B11)+COUNTBLANK(D11:E11)+COUNTBLANK(G11:G11)+COUNTBLANK(O11:AJ11)>0,"Faltan "&(COUNTBLANK(B11:B11)+COUNTBLANK(D11:E11)+COUNTBLANK(G11:G11)+COUNTBLANK(O11:AJ11))&" datos obligatorios",IF(NOT(ISNUMBER(B11)),"Fecha no válida",IF(N(B11)>TODAY(),"Fecha futura",IF(IFERROR(VLOOKUP(E11,LISTAS!$A$2:$C$65,3,FALSE),"")<>D11,"La subregión no corresponde al municipio",IF(IF(L11="",FALSE,OR(L11<0,L11>110)),"Edad fuera de rango",IF((V11="Sí")+(W11="Sí")+(X11="Sí")+(Y11="Sí")=0,"Marque al menos un tipo de violencia","OK")))))))
A12: =IF(OR(F12="",F12="Revisar",C12=""),"",F12&"-"&C12&"-"&TEXT(COUNTIFS($F$2:F12,F12,$C$2:C12,C12),"0000")) | C12: =IF(ISNUMBER(B12),YEAR(B12),"") | F12: =IF(E12="","",IFERROR(VLOOKUP(E12,LISTAS!$A$2:$C$65,2,FALSE),"Revisar")) | AK12: =IF(COUNTA(B12:B12)+COUNTA(D12:E12)+COUNTA(G12:AJ12)=0,"",IF(COUNTBLANK(B12:B12)+COUNTBLANK(D12:E12)+COUNTBLANK(G12:G12)+COUNTBLANK(O12:AJ12)>0,"Faltan "&(COUNTBLANK(B12:B12)+COUNTBLANK(D12:E12)+COUNTBLANK(G12:G12)+COUNTBLANK(O12:AJ12))&" datos obligatorios",IF(NOT(ISNUMBER(B12)),"Fecha no válida",IF(N(B12)>TODAY(),"Fecha futura",IF(IFERROR(VLOOKUP(E12,LISTAS!$A$2:$C$65,3,FALSE),"")<>D12,"La subregión no corresponde al municipio",IF(IF(L12="",FALSE,OR(L12<0,L12>110)),"Edad fuera de rango",IF((V12="Sí")+(W12="Sí")+(X12="Sí")+(Y12="Sí")=0,"Marque al menos un tipo de violencia","OK")))))))
A13: =IF(OR(F13="",F13="Revisar",C13=""),"",F13&"-"&C13&"-"&TEXT(COUNTIFS($F$2:F13,F13,$C$2:C13,C13),"0000")) | C13: =IF(ISNUMBER(B13),YEAR(B13),"") | F13: =IF(E13="","",IFERROR(VLOOKUP(E13,LISTAS!$A$2:$C$65,2,FALSE),"Revisar")) | AK13: =IF(COUNTA(B13:B13)+COUNTA(D13:E13)+COUNTA(G13:AJ13)=0,"",IF(COUNTBLANK(B13:B13)+COUNTBLANK(D13:E13)+COUNTBLANK(G13:G13)+COUNTBLANK(O13:AJ13)>0,"Faltan "&(COUNTBLANK(B13:B13)+COUNTBLANK(D13:E13)+COUNTBLANK(G13:G13)+COUNTBLANK(O13:AJ13))&" datos obligatorios",IF(NOT(ISNUMBER(B13)),"Fecha no válida",IF(N(B13)>TODAY(),"Fecha futura",IF(IFERROR(VLOOKUP(E13,LISTAS!$A$2:$C$65,3,FALSE),"")<>D13,"La subregión no corresponde al municipio",IF(IF(L13="",FALSE,OR(L13<0,L13>110)),"Edad fuera de rango",IF((V13="Sí")+(W13="Sí")+(X13="Sí")+(Y13="Sí")=0,"Marque al menos un tipo de violencia","OK")))))))
... A1001: =IF(OR(F1001="",F1001="Revisar",C1001=""),"",F1001&"-"&C1001&"-"&TEXT(COUNTIFS($F$2:F1001,F1001,$C$2:C1001,C1001),"0000")) | C1001: =IF(ISNUMBER(B1001),YEAR(B1001),"") | F1001: =IF(E1001="","",IFERROR(VLOOKUP(E1001,LISTAS!$A$2:$C$65,2,FALSE),"Revisar")) | AK1001: =IF(COUNTA(B1001:B1001)+COUNTA(D1001:E1001)+COUNTA(G1001:AJ1001)=0,"",IF(COUNTBLANK(B1001:B1001)+COUNTBLANK(D1001:E1001)+COUNTBLANK(G1001:G1001)+COUNTBLANK(O1001:AJ1001)>0,"Faltan "&(COUNTBLANK(B1001:B1001)+COUNTBLANK(D1001:E1001)+COUNTBLANK(G1001:G1001)+COUNTBLANK(O1001:AJ1001))&" datos obligatorios",IF(NOT(ISNUMBER(B1001)),"Fecha no válida",IF(N(B1001)>TODAY(),"Fecha futura",IF(IFERROR(VLOOKUP(E1001,LISTAS!$A$2:$C$65,3,FALSE),"")<>D1001,"La subregión no corresponde al municipio",IF(IF(L1001="",FALSE,OR(L1001<0,L1001>110)),"Edad fuera de rango",IF((V1001="Sí")+(W1001="Sí")+(X1001="Sí")+(Y1001="Sí")=0,"Marque al menos un tipo de violencia","OK")))))))

Sheet RESUMEN
A1: Resumen automático de la matriz
A3: Atenciones registradas | B3: =COUNTIF(MATRIZ!$AK$2:$AK$1001,"?*")
A4: Filas con «OK» | B4: =COUNTIF(MATRIZ!$AK$2:$AK$1001,"OK")
A5: Filas por corregir | B5: =B3-B4
A7: Violencia psicológica | B7: =COUNTIF(MATRIZ!$V$2:$V$1001,"Sí")
A8: Violencia física | B8: =COUNTIF(MATRIZ!$W$2:$W$1001,"Sí")
A9: Violencia sexual | B9: =COUNTIF(MATRIZ!$X$2:$X$1001,"Sí")
A10: Violencia económica | B10: =COUNTIF(MATRIZ!$Y$2:$Y$1001,"Sí")
A11: Intento de feminicidio | B11: =COUNTIF(MATRIZ!$Z$2:$Z$1001,"Sí")
A12: Feminicidio | B12: =COUNTIF(MATRIZ!$AA$2:$AA$1001,"Sí")
A14: Remisión Comisaría | B14: =COUNTIF(MATRIZ!$AD$2:$AD$1001,"Sí")
A15: Remisión Fiscalía | B15: =COUNTIF(MATRIZ!$AE$2:$AE$1001,"Sí")
A16: Remisión Salud | B16: =COUNTIF(MATRIZ!$AF$2:$AF$1001,"Sí")
A17: Remisión Policía | B17: =COUNTIF(MATRIZ!$AG$2:$AG$1001,"Sí")
A18: Remisión Defensoría | B18: =COUNTIF(MATRIZ!$AH$2:$AH$1001,"Sí")
A19: Remisión ICBF | B19: =COUNTIF(MATRIZ!$AI$2:$AI$1001,"Sí")
A21: Atenciones por municipio
A22: Municipio | B22: Código DANE | C22: Subregión | D22: Atenciones | E22: Último código
A23: =LISTAS!A2 | B23: =LISTAS!B2 | C23: =LISTAS!C2 | D23: =COUNTIF(MATRIZ!$E$2:$E$1001,A23) | E23: =IF(D23=0,"",LOOKUP(2,1/(MATRIZ!$F$2:$F$1001=B23),MATRIZ!$A$2:$A$1001))
A24: =LISTAS!A3 | B24: =LISTAS!B3 | C24: =LISTAS!C3 | D24: =COUNTIF(MATRIZ!$E$2:$E$1001,A24) | E24: =IF(D24=0,"",LOOKUP(2,1/(MATRIZ!$F$2:$F$1001=B24),MATRIZ!$A$2:$A$1001))
A25: =LISTAS!A4 | B25: =LISTAS!B4 | C25: =LISTAS!C4 | D25: =COUNTIF(MATRIZ!$E$2:$E$1001,A25) | E25: =IF(D25=0,"",LOOKUP(2,1/(MATRIZ!$F$2:$F$1001=B25),MATRIZ!$A$2:$A$1001))
A26: =LISTAS!A5 | B26: =LISTAS!B5 | C26: =LISTAS!C5 | D26: =COUNTIF(MATRIZ!$E$2:$E$1001,A26) | E26: =IF(D26=0,"",LOOKUP(2,1/(MATRIZ!$F$2:$F$1001=B26),MATRIZ!$A$2:$A$1001))
A27: =LISTAS!A6 | B27: =LISTAS!B6 | C27: =LISTAS!C6 | D27: =COUNTIF(MATRIZ!$E$2:$E$1001,A27) | E27: =IF(D27=0,"",LOOKUP(2,1/(MATRIZ!$F$2:$F$1001=B27),MATRIZ!$A$2:$A$1001))
A28: =LISTAS!A7 | B28: =LISTAS!B7 | C28: =LISTAS!C7 | D28: =COUNTIF(MATRIZ!$E$2:$E$1001,A28) | E28: =IF(D28=0,"",LOOKUP(2,1/(MATRIZ!$F$2:$F$1001=B28),MATRIZ!$A$2:$A$1001))
A29: =LISTAS!A8 | B29: =LISTAS!B8 | C29: =LISTAS!C8 | D29: =COUNTIF(MATRIZ!$E$2:$E$1001,A29) | E29: =IF(D29=0,"",LOOKUP(2,1/(MATRIZ!$F$2:$F$1001=B29),MATRIZ!$A$2:$A$1001))
A30: =LISTAS!A9 | B30: =LISTAS!B9 | C30: =LISTAS!C9 | D30: =COUNTIF(MATRIZ!$E$2:$E$1001,A30) | E30: =IF(D30=0,"",LOOKUP(2,1/(MATRIZ!$F$2:$F$1001=B30),MATRIZ!$A$2:$A$1001))
A31: =LISTAS!A10 | B31: =LISTAS!B10 | C31: =LISTAS!C10 | D31: =COUNTIF(MATRIZ!$E$2:$E$1001,A31) | E31: =IF(D31=0,"",LOOKUP(2,1/(MATRIZ!$F$2:$F$1001=B31),MATRIZ!$A$2:$A$1001))
A32: =LISTAS!A11 | B32: =LISTAS!B11 | C32: =LISTAS!C11 | D32: =COUNTIF(MATRIZ!$E$2:$E$1001,A32) | E32: =IF(D32=0,"",LOOKUP(2,1/(MATRIZ!$F$2:$F$1001=B32),MATRIZ!$A$2:$A$1001))
A33: =LISTAS!A12 | B33: =LISTAS!B12 | C33: =LISTAS!C12 | D33: =COUNTIF(MATRIZ!$E$2:$E$1001,A33) | E33: =IF(D33=0,"",LOOKUP(2,1/(MATRIZ!$F$2:$F$1001=B33),MATRIZ!$A$2:$A$1001))
A34: =LISTAS!A13 | B34: =LISTAS!B13 | C34: =LISTAS!C13 | D34: =COUNTIF(MATRIZ!$E$2:$E$1001,A34) | E34: =IF(D34=0,"",LOOKUP(2,1/(MATRIZ!$F$2:$F$1001=B34),MATRIZ!$A$2:$A$1001))
... A86: =LISTAS!A65 | B86: =LISTAS!B65 | C86: =LISTAS!C65 | D86: =COUNTIF(MATRIZ!$E$2:$E$1001,A86) | E86: =IF(D86=0,"",LOOKUP(2,1/(MATRIZ!$F$2:$F$1001=B86),MATRIZ!$A$2:$A$1001))

Sheet LISTAS
A1: MUNICIPIO | B1: CODIGO_DANE | C1: SUBREGION | E1: SUBREGION | F1: MUNICIPIO | G1: ZONA | H1: SINR | I1: SINO | J1: ETNIA | K1: GENERO | L1: ORIENTACION | M1: LUGAR | N1: AGRESOR | P1: MUNICIPIO_COMUNA | Q1: COMUNA | S1: MUNICIPIO_BARRIO | T1: BARRIO | V1: MUNICIPIO_CORREG | W1: CORREG | Y1: MUNICIPIO_VEREDA | Z1: VEREDA
A2: Albán | B2: 52019 | C2: Río Mayo | E2: Centro | F2: Albán | G2: Urbana | H2: Sí | I2: Sí | J2: Mestiza | K2: Mujer | L2: Heterosexual | M2: Vivienda | N2: Pareja | P2: Pasto | Q2: Comuna 1 | S2: Pasto | T2: 12 de Octubre | V2: Albán | W2: Campobello | Y2: Albán | Z2: Alto Delas Estrellas
A3: Aldana | B3: 52022 | C3: Obando | E3: Guambuyaco | F3: Aldana | G3: Rural | H3: No | I3: No | J3: Indígena | K3: Mujer trans | L3: Lesbiana | M3: Vía o espacio público | N3: Expareja | P3: Pasto | Q3: Comuna 2 | S3: Pasto | T3: 20 de Julio | V3: Albán | W3: Carmelo Asentamiento 1 | Y3: Albán | Z3: Betania
A4: Ancuya | B4: 52036 | C4: Occidente | E4: Juanambú | F4: Ancuya | H4: No registra | J4: Afrodescendiente | K4: Hombre | L4: Gay | M4: Lugar de trabajo | N4: Padre o padrastro | P4: Pasto | Q4: Comuna 3 | S4: Pasto | T4: 7 de Agosto | V4: Albán | W4: Fátima | Y4: Albán | Z4: Buenavista
A5: Arboleda | B5: 52051 | C5: Juanambú | E5: La Cordillera | F5: Arboleda | J5: Gitana (Rrom) | K5: Hombre trans | L5: Bisexual | M5: Institución educativa | N5: Madre o madrastra | P5: Pasto | Q5: Comuna 4 | S5: Pasto | T5: 8 de Marzo | V5: Aldana | W5: Guespud | Y5: Albán | Z5: Campobello
A6: Barbacoas | B6: 52079 | C6: Telembí | E6: La Sabana | F6: Barbacoas | J6: No registra | K6: Persona no binaria | L6: Otra | M6: Establecimiento de salud | N6: Hijo o hija | P6: Pasto | Q6: Comuna 5 | S6: Pasto | T6: Achalay | V6: Aldana | W6: Pamba Rosa | Y6: Albán | Z6: Cebadero
A7: Belén | B7: 52083 | C7: Río Mayo | E7: Los Abades | F7: Belén | K7: Otra | L7: No registra | M7: Transporte público | N7: Hermano o hermana | P7: Pasto | Q7: Comuna 6 | S7: Pasto | T7: Agualongo | V7: Aldana | W7: San Luis | Y7: Albán | Z7: Chapiurco
A8: Buesaco | B8: 52110 | C8: Juanambú | E8: Obando | F8: Buesaco | K8: No registra | M8: Bar, discoteca u hotel | N8: Otro familiar | P8: Pasto | Q8: Comuna 7 | S8: Pasto | T8: Aire Libre | V8: Ancuya | W8: Indo Santa Rosa | Y8: Albán | Z8: El Carmelo
A9: Chachagüí | B9: 52240 | C9: Centro | E9: Occidente | F9: Chachagüí | M9: Zona rural (finca o campo) | N9: Conocido o vecino | P9: Pasto | Q9: Comuna 8 | S9: Pasto | T9: Alahambra | V9: Arboleda | W9: El Empate | Y9: Albán | Z9: El Diviso
A10: Colón | B10: 52203 | C10: Río Mayo | E10: Pacífico Sur | F10: Colón | M10: Medios digitales o redes sociales | N10: Jefe, docente, funcionario o autoridad | P10: Pasto | Q10: Comuna 9 | S10: Pasto | T10: Alameda I | V10: Arboleda | W10: El Pedregal | Y10: Albán | Z10: El Salado
A11: Consacá | B11: 52207 | C11: Occidente | E11: Piedemonte Costero | F11: Consacá | M11: Otro lugar | N11: Actor armado | P11: Pasto | Q11: Comuna 10 | S11: Pasto | T11: Alameda Ii | V11: Arboleda | W11: Rosa Florida Sur - Sector la Capilla | Y11: Albán | Z11: El Socorro
A12: Contadero | B12: 52210 | C12: Obando | E12: Río Mayo | F12: Contadero | M12: No registra | N12: Desconocido | P12: Pasto | Q12: Comuna 11 | S12: Pasto | T12: Albergue del Sol | V12: Arboleda | W12: Rosaflorida Norte | Y12: Albán | Z12: Fátima
A13: Córdoba | B13: 52215 | C13: Obando | E13: Sanquianga | F13: Córdoba | N13: Otro | P13: Pasto | Q13: Comuna 12 | S13: Pasto | T13: Alcaldia de Pasto - Cam | V13: Barbacoas | W13: Altaquer | Y13: Albán | Z13: Guarangal
A14: Cuaspud Carlosama | B14: 52224 | C14: Obando | E14: Telembí | F14: Cuaspud Carlosama | N14: No registra | P14: San Andrés de Tumaco | Q14: Comuna 1 | S14: Pasto | T14: Altamira | V14: Barbacoas | W14: Cargazon | Y14: Albán | Z14: La Primavera
A15: Cumbal | B15: 52227 | C15: Obando | F15: Cumbal | P15: San Andrés de Tumaco | Q15: Comuna 2 | S15: Pasto | T15: Altos de Chapalito | V15: Barbacoas | W15: Cascajero | Y15: Albán | Z15: San Bosco
A16: Cumbitara | B16: 52233 | C16: La Cordillera | F16: Cumbitara | P16: San Andrés de Tumaco | Q16: Comuna 3 | S16: Pasto | T16: Altos de Chapalito Ii | V16: Barbacoas | W16: Chalchal | Y16: Albán | Z16: San Luis
A17: El Charco | B17: 52250 | C17: Sanquianga | F17: El Charco | P17: San Andrés de Tumaco | Q17: Comuna 4 | S17: Pasto | T17: Altos de Chapalito Iii | V17: Barbacoas | W17: Diaguillo | Y17: Albán | Z17: Tambo Alto
A18: El Peñol | B18: 52254 | C18: Guambuyaco | F18: El Peñol | P18: San Andrés de Tumaco | Q18: Comuna 5 | S18: Pasto | T18: Altos de la Carolina | V18: Barbacoas | W18: El Diviso | Y18: Albán | Z18: Tambo Bajo
A19: El Rosario | B19: 52256 | C19: La Cordillera | F19: El Rosario | S19: Pasto | T19: Altos de la Colina | V19: Barbacoas | W19: Junín | Y19: Albán | Z19: Viña
A20: El Tablón de Gómez | B20: 52258 | C20: Río Mayo | F20: El Tablón de Gómez | S20: Pasto | T20: Altos de la Floresta | V20: Barbacoas | W20: La Playa | Y20: Aldana | Z20: Caupueran
A21: El Tambo | B21: 52260 | C21: Guambuyaco | F21: El Tambo | S21: Pasto | T21: Altos de las Mercedes | V21: Barbacoas | W21: Los Brazos | Y21: Aldana | Z21: Chapuesmal
A22: Francisco Pizarro | B22: 52520 | C22: Pacífico Sur | F22: Francisco Pizarro | S22: Pasto | T22: Altos del Campo | V22: Barbacoas | W22: Mongón | Y22: Aldana | Z22: Chaquilulo
A23: Funes | B23: 52287 | C23: Obando | F23: Funes | S23: Pasto | T23: Altos del Lorenzo | V23: Barbacoas | W23: Ñambí | Y23: Aldana | Z23: Chitaira
A24: Guachucal | B24: 52317 | C24: Obando | F24: Guachucal | S24: Pasto | T24: Americas Norte | V24: Barbacoas | W24: Palo Seco | Y24: Aldana | Z24: Chorillo
A25: Guaitarilla | B25: 52320 | C25: La Sabana | F25: Guaitarilla | S25: Pasto | T25: Anganoy | V25: Barbacoas | W25: Pambana | Y25: Aldana | Z25: El Rosa
A26: Gualmatán | B26: 52323 | C26: Obando | F26: Gualmatán | S26: Pasto | T26: Aquine Alto I | V26: Barbacoas | W26: Paunde | Y26: Aldana | Z26: Guespud
A27: Iles | B27: 52352 | C27: Obando | F27: Iles | S27: Pasto | T27: Aquine Alto Ii | V27: Barbacoas | W27: Salí | Y27: Aldana | Z27: La Laguna
A28: Imués | B28: 52354 | C28: La Sabana | F28: Imués | S28: Pasto | T28: Aquine I | V28: Barbacoas | W28: San Juan Palacio | Y28: Aldana | Z28: Muesas
A29: Ipiales | B29: 52356 | C29: Obando | F29: Ipiales | S29: Pasto | T29: Aquine Ii | V29: Barbacoas | W29: San Miguel Nambí | Y29: Aldana | Z29: Pambarrosa
A30: La Cruz | B30: 52378 | C30: Río Mayo | F30: La Cruz | S30: Pasto | T30: Aquine Iii | V30: Barbacoas | W30: Sucre Guinulte | Y30: Aldana | Z30: San Luis
... A65: Yacuanquer | B65: 52885 | C65: Centro | F65: Yacuanquer | S65: Pasto | T65: Buenos Aires | V65: Córdoba | W65: Santander | Y65: Barbacoas | Z65: El Ceibo
S66: Pasto | T66: Caicedo | V66: Cuaspud Carlosama | W66: Macas | Y66: Barbacoas | Z66: El Peje
S67: Pasto | T67: Caicedonia | V67: Cumbal | W67: Chiles | Y67: Barbacoas | Z67: Guadual
S68: Pasto | T68: Calatrava | V68: Cumbal | W68: El Chota | Y68: Barbacoas | Z68: Huasano
S69: Pasto | T69: Calvario | V69: Cumbal | W69: La Calera | Y69: Barbacoas | Z69: Junin
S70: Pasto | T70: Camino Real | V70: Cumbal | W70: La Poma | Y70: Barbacoas | Z70: Kilometro 28
S71: Pasto | T71: Campos de Castilla | V71: Cumbal | W71: Nazate | Y71: Barbacoas | Z71: Kilometro 58
S72: Pasto | T72: Canchala | V72: Cumbal | W72: Panán | Y72: Barbacoas | Z72: La Falda
S73: Pasto | T73: Cantarana | V73: Cumbitara | W73: Campo Bello | Y73: Barbacoas | Z73: La Florida
S74: Pasto | T74: Capusigra | V74: Cumbitara | W74: Damasco | Y74: Barbacoas | Z74: La Marina
...
